Workbook

Sheet BUKU FIKSI&NON FIKSI
A1: d | B1: JUDUL BUKU | C1: KATEGORI | D1: DDC | E1: KETERANGAN | F1: PENULIS | G1: EDITOR | H1: PENERBIT | I1: ISBN | J1: TAHUN | K1: JML HAL | L1: JML BUKU | M1: GAMBAR | N1: KODE LABEL | O1: =COUNTA(B2:B1770) -> 1738 | P1: 000 | KARYA UMUM | Q1: =COUNTIF($C$2:$C1599,P1) -> 28 | R1: =Q1-COUNTIFS(M2:M1599,"-",C2:C1599,P1) -> 24 | S1: =Q1-R1 -> 4 | T1: =R1/Q1 -> 0.85714286 | U1: =sum(L2:L1750) -> 3635
A2: 1 | B2: PENGENALAN KOMPUTER | C2: 000 | KARYA UMUM | D2: 004 | E2: PEMROSESAN DATA, ILMU KOMPUTER, TEKNIK INFORMATIKA | F2: DRAJAT MUKTI | H2: EPSILON GRUP | I2: 9789794655245 | J2: 2011 | K2: 92 hlm; 28 cm | L2: 2 | M2: 004 Pengenalan Komputer.jpg | N2: =D2 & CHAR(10) & LEFT(F2,3) & CHAR(10) & LOWER(LEFT(B2,1)) -> 004 DRA p
A3: 2 | B3: ANEKA POSTER FILM DENGAN PHOTOSHOP | C3: 700 | SENI DAN OLAHRAGA | D3: 741.6 | E3: DESAIN GRAFIS | F3: AYU YUDHA | H3: PT. ELEX MEDIA KOMPUTINDO | I3: 9786020030623 | J3: 2012 | K3: 138 | L3: 1 | M3: 741.6 Aneka Poster Film dengan Photoshop.jpg | N3: =D3 & CHAR(10) & LEFT(F3,3) & CHAR(10) & LOWER(LEFT(B3,1)) -> 741.6 AYU a
A4: 3 | B4: ASYIKNYA JADI PENELITI | C4: 000 | KARYA UMUM | D4: 001.42 | E4: METODE RISET | F4: FAJAR M.N | G4: EDI WARSIDI | H4: PARIPUSTAKA | I4: 9786028712101 | J4: 2015 | K4: 58 | L4: 4 | M4: 001.42 Asyiknya Jadi Peneliti.jpg | N4: =D4 & CHAR(10) & LEFT(F4,3) & CHAR(10) & LOWER(LEFT(B4,1)) -> 001.42 FAJ a
A5: 4 | B5: AYO MEMBUAT KARYA ILMIAH | C5: 000 | KARYA UMUM | D5: 001.42 | E5: METODE RISET | F5: MARSA A.H. | G5: TIM ASSA GRAFIKA | H5: PT WANGSA JATRA LESTARI | I5: 978-979-040-148-8 | J5: 2015 | K5: 59 | L5: 1 | M5: 001.42 Ayo, Membuat Karya Ilmiah.jpg | N5: =D5 & CHAR(10) & LEFT(F5,3) & CHAR(10) & LOWER(LEFT(B5,1)) -> 001.42 MAR a
A6: 5 | B6: JURNALISTIK UNTUK REMAJA | C6: 000 | KARYA UMUM | D6: 070.4 | E6: JURNALISME, JURNALISTIK, PERS | F6: BAMBANG TRIMANSYAH | G6: BAMBANG TRIMANSYAH & FARIKA | H6: PT. KARYA KITA | I6: 979-9282-83-7 | J6: 2010 | K6: 74 | L6: 2 | M6: 070.4 Jurnalistik untuk Remaja.jpg | N6: =D6 & CHAR(10) & LEFT(F6,3) & CHAR(10) & LOWER(LEFT(B6,1)) -> 070.4 BAM j
A7: 6 | B7: BELAJAR MICROSOFT EXCEL | C7: 000 | KARYA UMUM | D7: 005.5 | E7: PROGRAM APLIKASI DENGAN KEGUNAAN KHUSUS | F7: REZKY, M | G7: EDI WARSIDI | H7: PT SARANA ILMU PUSTAKA | I7: 978-602-8714-14-3 | J7: 2015 | K7: 84 | L7: 3 | M7: 005.5 Belajar Microsoft Excel.jpg | N7: =D7 & CHAR(10) & LEFT(F7,3) & CHAR(10) & LOWER(LEFT(B7,1)) -> 005.5 REZ b
A8: 7 | B8: MAHIR MENGGUNAKAN MICROSOFT POWER POINT | C8: 000 | KARYA UMUM | D8: 005.5 | E8: PROGRAM APLIKASI DENGAN KEGUNAAN KHUSUS | F8: AMINUDIN | G8: EDI WARSIDI | H8: PT PURI DELCO | I8: 9786029571530 | J8: 2015 | K8: 54 | L8: 3 | M8: 005.5 Mahir Menggunakan Microsoft Power Point.jpg | N8: =D8 & CHAR(10) & LEFT(F8,3) & CHAR(10) & LOWER(LEFT(B8,1)) -> 005.5 AMI m
A9: 8 | B9: MENGENAL MICROSOFT WORD | C9: 000 | KARYA UMUM | D9: 005.5 | E9: PROGRAM APLIKASI DENGAN KEGUNAAN KHUSUS | F9: AMINUDIN | G9: EDI WARSIDI | H9: PT PURI DELCO | I9: 978-602-95715-4-7 | J9: 2013 | K9: 62 | L9: 3 | M9: 005.5 Mengenal Microsoft Word.jpg | N9: =D9 & CHAR(10) & LEFT(F9,3) & CHAR(10) & LOWER(LEFT(B9,1)) -> 005.5 AMI m
A10: 9 | B10: MENULIS KARANGAN ILMIAH | C10: 000 | KARYA UMUM | D10: 001.42 | E10: METODE RISET | F10: KOSASIH, M.Pd (E) | G10: NURHASANAH | H10: NOBEL EDUMEDIA | I10: 9786028219587 | J10: 2009 | K10: 110 | L10: 2 | M10: 001.42 Menulis Karangan Ilmiah.jpg | N10: =D10 & CHAR(10) & LEFT(F10,3) & CHAR(10) & LOWER(LEFT(B10,1)) -> 001.42 KOS m
A11: 10 | B11: KETERAMPILAN DASAR KOMPUTER | C11: 000 | KARYA UMUM | D11: 004 | E11: PEMROSESAN DATA, ILMU KOMPUTER, TEKNIK INFORMATIKA | F11: AMINUDIN | G11: EDI WARSIDI | H11: PT PURI DELCO | I11: 978-602-95715-1-6 | J11: 2013 | K11: 66 | L11: 2 | M11: 004 Keterampilan Dasar Komputer.jpg | N11: =D11 & CHAR(10) & LEFT(F11,3) & CHAR(10) & LOWER(LEFT(B11,1)) -> 004 AMI k
A12: 11 | B12: MENGENAL DAN MEMANFAATKAN INTERNET | C12: 000 | KARYA UMUM | D12: 046.78 | E12: INTERNET | F12: TEDI RUSTENDI | G12: TIM SPKN | H12: PT. SARANA | I12: 978-979-678-403-5 | J12: 2014 | K12: 82 | L12: 1 | M12: 046.78 Mengenal dan Memanfaatkan Internet.jpg | N12: =D12 & CHAR(10) & LEFT(F12,3) & CHAR(10) & LOWER(LEFT(B12,1)) -> 046.78 TED m
A13: 12 | B13: TERAMPIL MENGGUNAKAN INTERNET | C13: 000 | KARYA UMUM | D13: 004.678 | E13: INTERNET | F13: AMINUDIN | G13: EDI WARSIDI | H13: PT. PURI DELCO | I13: 9786029571554 | J13: 2015 | K13: 99 | L13: 2 | M13: 004.678 Terampil Menggunakan Internet.jpg | N13: =D13 & CHAR(10) & LEFT(F13,3) & CHAR(10) & LOWER(LEFT(B13,1)) -> 004.678 AMI t
A14: 13 | B14: MARI MENGENAL KOMPUTER | C14: 000 | KARYA UMUM | D14: 004 | E14: PEMROSESAN DATA, ILMU KOMPUTER, TEKNIK INFORMATIKA | F14: ZAMRUD TUALEKA - MANSHUR TUALEKA, dkk | G14: ROHMAT | H14: PT MITRA AKSARA PANAITAN | I14: 978-602-8262-15-6 | J14: 2014 | K14: 60 | L14: 1 | M14: 004 Mari Mengenal Komputer.jpg | N14: =D14 & CHAR(10) & LEFT(F14,3) & CHAR(10) & LOWER(LEFT(B14,1)) -> 004 ZAM m
A15: 14 | B15: MARI MENGENAL LEMBAR KERJA (Ms. EXCEL) | C15: 000 | KARYA UMUM | D15: 005.5 | E15: PROGRAM APLIKASI DENGAN KEGUNAAN KHUSUS | F15: ZAMRUD TUALEKA - MANSHUR TUALEKA, dkk | G15: WULAN ANGGRAENI | H15: PT MITRA AKSARA PANAITAN | I15: 978-602-8262-17-0 | J15: 2014 | K15: 52 | L15: 1 | M15: 005.5 Mari Mengenal Lembar Kerja (Ms. Excel).jpg | N15: =D15 & CHAR(10) & LEFT(F15,3) & CHAR(10) & LOWER(LEFT(B15,1)) -> 005.5 ZAM m
A16: 15 | B16: JENIS-JENIS PUBLIKASI ILMIAH & SISTEMATIKA PENULISANNYA | C16: 000 | KARYA UMUM | D16: 001.42 | E16: METODE RISET | F16: SUWANTO, M.Pd. | G16: AMIN MUSTOFA | H16: PUSTAKA INTERMEDIA | I16: 9786025125911 | J16: 2018 | K16: 128 hlm; 14 x 21 cm | L16: 1 | M16: 001.42 Jenis-Jenis Publikasi Ilmiah & Sistematika Penulisannya.jpg | N16: =D16 & CHAR(10) & LEFT(F16,3) & CHAR(10) & LOWER(LEFT(B16,1)) -> 001.42 SUW j
A17: 16 | B17: MENYUSUN KARYA TULIS ILMIAH UNTUK MEMPEROLEH ANGKA KARYA KREDIT | C17: 000 | KARYA UMUM | D17: 001.42 | E17: METODE RISET | F17: NANA SUDJANA, (DR.R H. ), DRS. H. ULUNG LAKSAMANA | G17: HARRY SURYANA | H17: SINAR BARU ALGENSINDO | J17: 2002 | K17: 82 | L17: 1 | M17: 001.42 Menyusun Karya Tulis Ilmiah - Untuk Memperoleh Angka Kredit.jpg | N17: =D17 & CHAR(10) & LEFT(F17,3) & CHAR(10) & LOWER(LEFT(B17,1)) -> 001.42 NAN m
A18: 17 | B18: TERAMPIL MEMBUAT BLOG DAN ACCOUNT JEJARING SOSIAL | C18: 000 | KARYA UMUM | D18: 006.752 | E18: BLOG, WEB BLOG | F18: AMINUDIN | G18: EDI WARSIDI | H18: PT PURI DELCO | I18: 378-602-8713-02-3 | J18: 2015 | K18: 158 | L18: 2 | M18: - | N18: =D18 & CHAR(10) & LEFT(F18,3) & CHAR(10) & LOWER(LEFT(B18,1)) -> 006.752 AMI t
A19: 18 | B19: KIAT MENULIS KARYA ILMIAH | C19: 000 | KARYA UMUM | D19: 001.42 | E19: METODE RISET | F19: DIAH ERNA TRININGSIH | G19: RAHMAT ISNAINI | H19: INTAN PARIWARA | J19: 2008 | K19: 68 | L19: 1 | M19: 001.42 Kiat Menulis Karya Ilmiah.jpg | N19: =D19 & CHAR(10) & LEFT(F19,3) & CHAR(10) & LOWER(LEFT(B19,1)) -> 001.42 DIA k
A20: 19 | B20: KAMUS TEKNOLOGI INFORMASI KOMUNIKASI | C20: 000 | KARYA UMUM | D20: 004 | E20: KOMPUTER | F20: UTAMI HANDAYANI, S.I.KOM | G20: KUNCORO | H20: MITRA EDUKASI | I20: 978-602-1388-06-8 | J20: 2014 | K20: 196 | L20: 3 | M20: 004 Kamus Teknologi Informasi Komunikasi.jpg | N20: =D20 & CHAR(10) & LEFT(F20,3) & CHAR(10) & LOWER(LEFT(B20,1)) -> 004 UTA k
A21: 20 | B21: BEKERJA SEBAGAI WARTAWAN | C21: 000 | KARYA UMUM | D21: 070.4 | E21: JURNALISME, JURNALISTIK, PERS | F21: FITRIYAN DENNIS | G21: DANIEL P. PURBA & YATI SUMIHARTI | H21: PENERBIT ERLANGGA | I21: 978-979-015-790-3 | J21: 2008 | K21: 86 | L21: 1 | M21: 070.4 Bekerja Sebagai Wartawan.jpg | N21: =D21 & CHAR(10) & LEFT(F21,3) & CHAR(10) & LOWER(LEFT(B21,1)) -> 070.4 FIT b
A22: 21 | B22: YANG PERLU KITA KETAHUI | C22: 000 | KARYA UMUM | D22: 001 | E22: ILMU PENGETAHUAN | F22: FADLAN OETAMA | G22: ANISAH SABRINA | H22: CV IASHA JAYA | I22: 9786028131070 | J22: 2018 | K22: 58 hlm; 14,5x21 cm | L22: 4 | M22: 001 Yang Perlu Kita Ketahui.jpg | N22: =D22 & CHAR(10) & LEFT(F22,3) & CHAR(10) & LOWER(LEFT(B22,1)) -> 001 FAD y
A23: 22 | B23: MENGENAL PENGOLAH GAMBAR TUX PAINT | C23: 000 | KARYA UMUM | D23: 006.66 | E23: PEMROGRAMAN UNTUK KOMPUTER GRAFIS | F23: SRI HUNING | G23: SUPARDI | H23: PUSTAKA TIGA KELANA | I23: 978-979-091-080-5 | J23: 2015 | K23: 60 | L23: 1 | M23: - | N23: =D23 & CHAR(10) & LEFT(F23,3) & CHAR(10) & LOWER(LEFT(B23,1)) -> 006.66 SRI m
A24: 23 | B24: ENSIKLOPEDI ANAK NASIONAL | C24: 000 | KARYA UMUM | D24: 031 | E24: ENSIKLOPEDIA UMUM DALAM BAHASA INDONESIA | H24: PT DELTA PAMUNGKAS | I24: 979-9327-25-3 | J24: 2012 | K24: 152 | L24: 1 | M24: - | N24: =D24 & CHAR(10) & LEFT(F24,3) & CHAR(10) & LOWER(LEFT(B24,1)) -> 031 e
A25: 24 | B25: MENGENAL PERANGKAT LUNAK KOMPUTER | C25: 000 | KARYA UMUM | D25: 005.1 | E25: PEMROGRAMAN | F25: BAGAS SHINUGI | H25: MEDIANTARA SEMESTA | I25: 978-602-8489-63-8 | J25: 2012 | K25: 56 hlm; 25 cm | L25: 1 | M25: 005.1 Mengenal Perangkat Lunak Komputer.jpg | N25: =D25 & CHAR(10) & LEFT(F25,3) & CHAR(10) & LOWER(LEFT(B25,1)) -> 005.1 BAG m
A26: 25 | B26: ANEKA KREASI GRAFIS DENGAN COREL DRAW | C26: 000 | KARYA UMUM | D26: 006.66 | E26: PEMROGRAMAN UNTUK KOMPUTER GRAFIS | F26: DIKY RAHMAT YUSUF SOBARI | G26: A. RUHIMAT | H26: TIGA SERANGKAI | I26: 987-979-045-850-5 | J26: 2009 | K26: 58 | L26: 1 | M26: - | N26: =D26 & CHAR(10) & LEFT(F26,3) & CHAR(10) & LOWER(LEFT(B26,1)) -> 006.66 DIK a
A27: 26 | B27: ENSIKLOPEDI ANAK NASIONAL 9 | SOEPRATMAN, WAGE RUDOLF SAMPAI TUBERKOLOSIS | C27: 000 | KARYA UMUM | D27: 031 | E27: ENSIKLOPEDIA UMUM DALAM BAHASA INDONESIA | F27: CONNY R. SEMIAWAN, Prof. Dr. | H27: PT DELTA PAMUNGKAS | I27: 979-9327-28-8 | J27: 2009 | K27: 144 | L27: 1 | M27: 031 ENSIKLOPEDI ANAK NASIONAL 9 | SOEPRATMAN, WAGE RUDOLF SAMPAI TUBERKOLOSIS.jpg | N27: =D27 & CHAR(10) & LEFT(F27,3) & CHAR(10) & LOWER(LEFT(B27,1)) -> 031 CON e
A28: 27 | B28: THE GIRL'S GUIDE TO BEING A BOSS | C28: 100 | FILSAFAT & PSIKOLOGI | D28: 158.4 | E28: KEPEMIMPINAN YANG BERKAITAN DENGAN PSIKOLOGI | F28: CAITLIN FRIEDMAN KIMBERLY YORIO | H28: PUBLISHING ONE | I28: 978-602-95079-7-3 | J28: 2009 | K28: 266 | L28: 1 | M28: 154.8 The Girl's Guide to Being a Boss.jpg | N28: =D28 & CHAR(10) & LEFT(F28,3) & CHAR(10) & LOWER(LEFT(B28,1)) -> 158.4 CAI t
A29: 28 | B29: LOGIKA | C29: 100 | FILSAFAT & PSIKOLOGI | D29: 160 | E29: LOGIKA, ILMU TENTANG PEMIKIRAN | F29: MUNDIRI, Drs. H. | H29: PT. RAJA GRAFINDO PERSADA | I29: 979-421-398-5 | J29: 2014 | K29: 227 / A5 | L29: 1 | M29: - | N29: =D29 & CHAR(10) & LEFT(F29,3) & CHAR(10) & LOWER(LEFT(B29,1)) -> 160 MUN l
A30: 29 | B30: ETIKET BERGAUL | C30: 100 | FILSAFAT & PSIKOLOGI | D30: 177 | E30: ETIKA DALAM HUBUNGAN SOSIAL PERGAULAN | F30: SARUMPAET, R.I. | H30: PUBLISHING HOUSE | I30: 979-504-019-7 | J30: 2006 | K30: 143 / A5 | L30: 1 | M30: - | N30: =D30 & CHAR(10) & LEFT(F30,3) & CHAR(10) & LOWER(LEFT(B30,1)) -> 177 SAR e
A31: 30 | B31: INDAHNYA SIKAP BERSAING SECARA SEHAT | C31: 100 | FILSAFAT & PSIKOLOGI | D31: 177 | E31: ETIKA DALAM HUBUNGAN SOSIAL PERGAULAN | F31: EDI WARSIDI | G31: RISSA YANUAR, S.S | H31: CV. PRINGGANDANI | I31: - | J31: 2011 | K31: 72 / A5 | L31: 2 | M31: 177 Indahnya Sikap Bersaing Secara Sehat.jpg | N31: =D31 & CHAR(10) & LEFT(F31,3) & CHAR(10) & LOWER(LEFT(B31,1)) -> 177 EDI i
A32: 31 | B32: KARAKTER KEPAHLAWANAN | C32: 100 | FILSAFAT & PSIKOLOGI | D32: 155.2 | E32: PSIKOLOGI INDIVIDUAL, KARAKTER | F32: RENDI HERMANA | G32: S. YUGANTARA | H32: CV. GEMA BUKU NUSANTARA | I32: 9786029110333 | J32: 2015 | K32: 65 / A5 | L32: 1 | M32: - | N32: =D32 & CHAR(10) & LEFT(F32,3) & CHAR(10) & LOWER(LEFT(B32,1)) -> 155.2 REN k
A33: 32 | B33: MARI MENGINTIP OTAK SASTRAWAN | C33: 100 | FILSAFAT & PSIKOLOGI | D33: 153 | E33: INTELEGENSIA, KECERDASAN PROSES INTELEKTUAL DAN MENTAL | F33: NIA HARYANTO | G33: EKO M | H33: CV. MEDIA SARANA CERDAS | I33: 978-602-9108-05-7 | J33: 2015 | K33: 66 | L33: 4 | M33: 153 Mari Mengintip Otak Sastrawan.jpg | N33: =D33 & CHAR(10) & LEFT(F33,3) & CHAR(10) & LOWER(LEFT(B33,1)) -> 153 NIA m
A34: 33 | B34: KEPERCAYAAN DIRI | C34: 100 | FILSAFAT & PSIKOLOGI | D34: 155.25 | E34: PERKEMBANGAN KEPRIBADIAN, PERKEMBANGAN KARAKTER | F34: GINA FAUZIAH | G34: TIM EDITOR | H34: CV WACANA GELORA CIPTA | I34: 978-602-8808-02-6 | J34: 2009 | K34: 76 | L34: 2 | M34: 155.25 Kepercayaan Diri.jpg | N34: =D34 & CHAR(10) & LEFT(F34,3) & CHAR(10) & LOWER(LEFT(B34,1)) -> 155.25 GIN k
A35: 34 | B35: TUNJUKKAN DIRIMU | C35: 100 | FILSAFAT & PSIKOLOGI | D35: 155.5 | E35: PSIKOLOGI REMAJA | F35: NILAM PERMATA | G35: NILAM PERMATA | H35: NOBEL EDUMEDIA | I35: 978-602-8691-86-4 | J35: 2010 | K35: 161 /A5 | L35: 2 | M35: - | N35: =D35 & CHAR(10) & LEFT(F35,3) & CHAR(10) & LOWER(LEFT(B35,1)) -> 155.5 NIL t
A36: 35 | B36: KISAH INSPIRATIF YANG MEMPERKAYA KARAKTER | C36: 100 | FILSAFAT & PSIKOLOGI | D36: 155.2 | E36: PSIKOLOGI INDIVIDUAL, KARAKTER | F36: EDI WARSIDI | G36: TIM EDITOR | H36: PURIPUSTAKA | I36: 978-602-8712-94-1 | J36: 2015 | K36: 114 | L36: 5 | M36: 155.2 Kisah Inspiratif yang Memperkaya Karakter.jpg | N36: =D36 & CHAR(10) & LEFT(F36,3) & CHAR(10) & LOWER(LEFT(B36,1)) -> 155.2 EDI k
A37: 36 | B37: MELAWAN HAMBATAN DENGAN KARAKTER MENAWAN | C37: 100 | FILSAFAT & PSIKOLOGI | D37: 155.2 | E37: PERKEMBANGAN KEPRIBADIAN, PERKEMBANGAN KARAKTER | F37: EDI WARSIDI | G37: TIM EDITOR PURIPUSTAKA | H37: PURIPUSTAKA | I37: 978-602-8712-95-8 | J37: 98 | K37: 98 | L37: 1 | M37: - | N37: =D37 & CHAR(10) & LEFT(F37,3) & CHAR(10) & LOWER(LEFT(B37,1)) -> 155.2 EDI m
A38: 37 | B38: MARI, MENGINTIP OTAK POLITIKUS | C38: 100 | FILSAFAT & PSIKOLOGI | D38: 153 | E38: INTELEGENSIA, KECERDASAN PROSES INTELEKTUAL DAN MENTAL | F38: NIA HARYANTO | G38: AHSA | H38: CV. MEDIA SARANA CERDAS | I38: 978-602-9108-08-8 | J38: 2015 | K38: 58 | L38: 4 | M38: - | N38: =D38 & CHAR(10) & LEFT(F38,3) & CHAR(10) & LOWER(LEFT(B38,1)) -> 153 NIA m
A39: 38 | B39: CERDAS & CERGAS MENJAGA ETIKET | C39: 100 | FILSAFAT & PSIKOLOGI | D39: 177 | E39: ETIKA DALAM HUBUNGAN SOSIAL PERGAULAN | F39: DIDA YUGANTARA, S.R | G39: M. HABIBIE | H39: PUSTAKA SUNDA | I39: 978-602-9124-28-6 | J39: 2009 | K39: 58 | L39: 1 | M39: 177 Cerdas & Cergas Menjaga Etiket.jpg | N39: =D39 & CHAR(10) & LEFT(F39,3) & CHAR(10) & LOWER(LEFT(B39,1)) -> 177 DID c
A40: 39 | B40: MARI, MENGINTIP OTAK MUSISI | C40: 100 | FILSAFAT & PSIKOLOGI | D40: 153 | E40: INTELEGENSIA, KECERDASAN PROSES INTELEKTUAL DAN MENTAL | F40: NIA HARYANTO | G40: PUTRI | H40: CV MEDIA SARANA CERDAS | I40: 9786029108071 | J40: 2015 | K40: 53 | L40: 3 | M40: 153 Mari, Mengintip Otak Musisi.jpg | N40: =D40 & CHAR(10) & LEFT(F40,3) & CHAR(10) & LOWER(LEFT(B40,1)) -> 153 NIA m
...

Sheet E book
A1: d | B1: JUDUL BUKU | C1: KATEGORI | D1: DDC | E1: KETERANGAN | F1: PENULIS / PENERJEMAH | G1: EDITOR | H1: PENERBIT | I1: ISBN | J1: TAHUN | K1: JML HAL | L1: JML BUKU | M1: GAMBAR | N1: KODE LABEL | O1: =COUNTA(B2:B1650) -> 27 | P1: 800 | KESUSASTRAAN | Q1: =COUNTIF($C$2:$C1600,P1) -> 25 | R1: =Q1-COUNTIFS(M2:M1600,"-",C2:C1600,P1) -> 25 | S1: =Q1-R1 -> 0 | T1: =R1/Q1 -> 1 | U1: =sum(L2:L1600) -> 25
A2: 1 | B2: DUNIA SHOPIE : SEBUAH NOVEL FILSAFAT | C2: 800 | KESUSASTRAAN | D2: 813 | E2: NOVEL | F2: JOSTEIN GAARDER | G2: YULIANI LIPUTO, ANDITYAS PRABANTORO | H2: PT. MIZAN PUSTAKA | I2: 978-979-433-574-1 | J2: 2014 | K2: 798 | L2: 1 | M2: e 813 Dunia Sophie .jpg | N2: =D2 & CHAR(10) & LEFT(F2,3) & CHAR(10) & LOWER(LEFT(B2,1)) -> 813 JOS d
A3: 2 | B3: ANCIKA: DIA YANG BERSAMAKU TAHUN 1995 | C3: 800 | KESUSASTRAAN | D3: 813 | E3: NOVEL | F3: PIDI BAIQ | G3: Esti Ayu Budihabsari Ilham Miftahuddin | H3: PT Mizan Pustaka | I3: 978-602-6716-90-3 | J3: 2021 | K3: 340 hal | L3: 1 | M3: e 813 Ancika - Dia yang Bersamaku Tahun 1995.jpg | N3: =D3 & CHAR(10) & LEFT(F3,3) & CHAR(10) & LOWER(LEFT(B3,1)) -> 813 PID a
A4: 3 | B4: ANIMAL FARM | C4: 800 | KESUSASTRAAN | D4: 813 | E4: NOVEL | F4: GEORGE ORWELL / PROF. BAKDI SOEMANTO | G4: Ika Yuliana Kurniasih | H4: PT Bentang Pustaka, Yogyakarta | I4: 978-602-291-283-5 | J4: 2016 | K4: 144 hlm,; 20,5 cm | L4: 1 | M4: e 813 Animal Farm.jpg | N4: =D4 & CHAR(10) & LEFT(F4,3) & CHAR(10) & LOWER(LEFT(B4,1)) -> 813 GEO a
A5: 4 | B5: ARGANTARA | C5: 800 | KESUSASTRAAN | D5: 813 | E5: NOVEL | F5: FALISTIYANA | G5: Rahastri Fajar Puspasari | H5: PT Sarana Kreasi Abadi, Depok | J5: 2021 | K5: 484 hal.; 14,5 x 20,5 cm | L5: 1 | M5: e 813 Argantara.jpg | N5: =D5 & CHAR(10) & LEFT(F5,3) & CHAR(10) & LOWER(LEFT(B5,1)) -> 813 FAL a
A6: 5 | B6: BIDADARI BERSAYAP BIRU | C6: 800 | KESUSASTRAAN | D6: 813 | E6: NOVEL | F6: AGNES JESSICA | H6: PT Gramedia Pustaka Utama, Jakarta | I6: 978-602-03-7594-6 | J6: 2017 | K6: 224 hlm.; 20 cm | L6: 1 | M6: e 813 Bidadari Bersayap Biru.jpg | N6: =D6 & CHAR(10) & LEFT(F6,3) & CHAR(10) & LOWER(LEFT(B6,1)) -> 813 AGN b
A7: 6 | B7: BUMI | C7: 800 | KESUSASTRAAN | D7: 813 | E7: NOVEL | F7: TERE LIYE | G7: Danya Putri Triana Rahmawati | H7: PT Gramedia Pustaka Utama, Jakarta | I7: 978-602-03-0112-9 | J7: 2014 | K7: 440 hal; 20 cm | L7: 1 | M7: e 813 Bumi.jpg | N7: =D7 & CHAR(10) & LEFT(F7,3) & CHAR(10) & LOWER(LEFT(B7,1)) -> 813 TER b
A8: 7 | B8: CANDIDE (Candide ou l’OptimIsme) | C8: 800 | KESUSASTRAAN | D8: 813 | E8: NOVEL | F8: VOLTAIRE / IDA SUNDARI HUSEIN | H8: Kepustakaan Populer Gramedia, Jakarta | I8: 978-602-424-160-5 | J8: 2016 | K8: 154 hlm.; 14 x 21 cm | L8: 1 | M8: e 813 Candide.jpg | N8: =D8 & CHAR(10) & LEFT(F8,3) & CHAR(10) & LOWER(LEFT(B8,1)) -> 813 VOL c
A9: 8 | B9: ENIGMA 2: MENGUAK FAKTA-FAKTA MISTERIUS PALING FENOMENAL DI DUNIA | C9: 000 | KARYA UMUM | D9: 001 | E9: KRIPTOGRAFI / MISTERI | F9: SAM | G9: Tina Leoni | H9: Tangga Pustaka, Jakarta | I9: 978-979-083-086-6 | J9: 2013 | K9: viii + 284 hlm.; 20 cm | L9: 1 | M9: e 813 Enigma 2.jpg | N9: =D9 & CHAR(10) & LEFT(F9,3) & CHAR(10) & LOWER(LEFT(B9,1)) -> 001 SAM e
A10: 9 | B10: ENIGMA: MENGUAK FAKTA-FAKTA MISTERIUS PALING FENOMENAL DI DUNIA (JILID 1) | C10: 000 | KARYA UMUM | D10: 001 | E10: MISTERI / HOAKS DUNIA | F10: SAM | G10: Tina Leoni | H10: Tangga Pustaka, Jakarta | I10: 979-083-077-7 | J10: 2013 | K10: x + 286 hlm.; 20 cm | L10: 1 | M10: e 813 Enigma.jpg | N10: =D10 & CHAR(10) & LEFT(F10,3) & CHAR(10) & LOWER(LEFT(B10,1)) -> 001 SAM e
A11: 10 | B11: ERAGON (WARISAN: BUKU SATU) | C11: 800 | KESUSASTRAAN | D11: 813 | E11: NOVEL | F11: CHRISTOPHER PAOLINI / SENDRA B. TANUWIDJAYA | H11: PT Gramedia Pustaka Utama, Jakarta | I11: 978-979-22-0862-7 | J11: 2004 | K11: 568 hlm.; 23 cm | L11: 1 | M11: e 813 Eragon.jpg | N11: =D11 & CHAR(10) & LEFT(F11,3) & CHAR(10) & LOWER(LEFT(B11,1)) -> 813 CHR e
A12: 11 | B12: FUNICULI FUNICULA 2: KISAH-KISAH YANG BARU TERUNGKAP | C12: 800 | KESUSASTRAAN | D12: 813 | E12: NOVEL | F12: TOSHIKAZU KAWAGUCHI | H12: PT Gramedia Pustaka Utama, Jakarta | I12: 978-602-06-6384-5 | J12: 2022 | K12: 200 hlm.; 20 cm | L12: 1 | M12: e 813 funiculi funicula - Kisah-kisah yang baru terungkap.jpg | N12: =D12 & CHAR(10) & LEFT(F12,3) & CHAR(10) & LOWER(LEFT(B12,1)) -> 813 TOS f
A13: 12 | B13: FUNICULI FUNICULA : BEFORE THE COFFEE GETS COLD | C13: 800 | KESUSASTRAAN | D13: 813 | E13: NOVEL | F13: TOSHIKAZU KAWAGUCHI | H13: PT Gramedia Pustaka Utama, Jakarta | I13: 978-602-06-5194-1 | J13: 2021 | K13: 224 hal.; 20 cm | L13: 1 | M13: e 813 Funiculi Funicula Before the Coffee Gets Cold.jpg | N13: =D13 & CHAR(10) & LEFT(F13,3) & CHAR(10) & LOWER(LEFT(B13,1)) -> 813 TOS f
A14: 13 | B14: DONA DONA (FUNICULI FUNICULA #3) | C14: 800 | KESUSASTRAAN | D14: 813 | E14: NOVEL | F14: TOSHIKAZU KAWAGUCHI | H14: PT Gramedia Pustaka Utama, Jakarta | I14: 978-602-06-7172-7 | J14: 2023 | K14: 264 hlm.; 20 cm | L14: 1 | M14: e 813 Funiculi Funicula3 Dona Dona.jpg | N14: =D14 & CHAR(10) & LEFT(F14,3) & CHAR(10) & LOWER(LEFT(B14,1)) -> 813 TOS d
A15: 14 | B15: HARRY POTTER AND THE SORCERER'S STONE (HARRY POTTER #1) | C15: 800 | KESUSASTRAAN | D15: 813 | E15: NOVEL | F15: J. K. ROWLING | K15: 384 hlm.; 20 cm | L15: 1 | M15: e 813 Harry Potter and The Socrer's Stone.jpg | N15: =D15 & CHAR(10) & LEFT(F15,3) & CHAR(10) & LOWER(LEFT(B15,1)) -> 813 J. h
A16: 15 | B16: HARRY POTTER AND THE CHAMBER OF SECRETS (HARRY POTTER #2) | C16: 800 | KESUSASTRAAN | D16: 813 | E16: NOVEL | F16: J. K. ROWLING | K16: 424 hlm.; 20 cm | L16: 1 | M16: e 813 Harry Potter and the Chamber of Secrets.jpg | N16: =D16 & CHAR(10) & LEFT(F16,3) & CHAR(10) & LOWER(LEFT(B16,1)) -> 813 J. h
A17: 16 | B17: HARRY POTTER AND THE PRISONER OF AZKABAN (HARRY POTTER #3) | C17: 800 | KESUSASTRAAN | D17: 813 | E17: NOVEL | F17: J. K. ROWLING | K17: 544 hlm.; 20 cm | L17: 1 | M17: e 813 Harry Potter and the Prisoner of Azkaban.jpg | N17: =D17 & CHAR(10) & LEFT(F17,3) & CHAR(10) & LOWER(LEFT(B17,1)) -> 813 J. h
A18: 17 | B18: HARRY POTTER DAN ORDER PHOENIX (HARRY POTTER #5) | C18: 800 | KESUSASTRAAN | D18: 813 | E18: NOVEL | F18: J. K. ROWLING | K18: 1208 hlm.; 20 cm | L18: 1 | M18: e 813 Harry Potter and the Order of the Phoenix.jpg | N18: =D18 & CHAR(10) & LEFT(F18,3) & CHAR(10) & LOWER(LEFT(B18,1)) -> 813 J. h
A19: 18 | B19: HARRY POTTER AND THE DEATHLY HALLOWS (HARRY POTTER #7) | C19: 800 | KESUSASTRAAN | D19: 813 | E19: NOVEL | F19: J. K. ROWLING | K19: 992 hlm.; 20 cm | L19: 1 | M19: e 813 Harry Potter and the Deathly Hallows.jpg | N19: =D19 & CHAR(10) & LEFT(F19,3) & CHAR(10) & LOWER(LEFT(B19,1)) -> 813 J. h
A20: 19 | B20: HELLO, CELLO. | C20: 800 | KESUSASTRAAN | D20: 813 | E20: NOVEL | F20: NADIA RISTIVANI | G20: Dono Salim | H20: PT. Bukune Kreatif Cipta, Jakarta | I20: 978-602-22-0438-1 | J20: 2022 | K20: 432 hlm.; 13 x 19 cm | L20: 1 | M20: e 813 Hello, Cello by Nadia Ristivani.jpg | N20: =D20 & CHAR(10) & LEFT(F20,3) & CHAR(10) & LOWER(LEFT(B20,1)) -> 813 NAD h
A21: 20 | B21: JAKARTA SEBELUM PAGI | C21: 800 | KESUSASTRAAN | D21: 813 | E21: NOVEL | F21: ZIGGY ZEZSYAZEOVIENNAZABRIZKIE | H21: PT. Gramedia Widyasarana Indonesia, Jakarta | I21: 978-602-375-844-9 | J21: 2017 | K21: 280 hlm.; 20 cm | L21: 1 | M21: e 813 Jakarta sebelum pagi.jpg | N21: =D21 & CHAR(10) & LEFT(F21,3) & CHAR(10) & LOWER(LEFT(B21,1)) -> 813 ZIG j
A22: 21 | B22: JINGGA JENAKA | C22: 800 | KESUSASTRAAN | D22: 811 | E22: PUISI | F22: ANNISA RIZKIANA RAHMASARI | H22: Kepustakaan Populer Gramedia, Jakarta | I22: 978-602-481-110-5 | J22: 2019 | K22: ix + 118 hlm.; 11,5 x 17,5 cm | L22: 1 | M22: e 813 jingga jenaka.jpg | N22: =D22 & CHAR(10) & LEFT(F22,3) & CHAR(10) & LOWER(LEFT(B22,1)) -> 811 ANN j
A23: 22 | B23: SANG PUJAAN | C23: 800 | KESUSASTRAAN | D23: 813 | E23: NOVEL | F23: KAHLIL GIBRAN | H23: TUGU, Yogyakarta | J23: 2003 | K23: 149 hlm.; 14 x 20 cm | M23: e 813 kahlil gibran sang pujaan.jpg | N23: =D23 & CHAR(10) & LEFT(F23,3) & CHAR(10) & LOWER(LEFT(B23,1)) -> 813 KAH s
A24: 23 | B24: KEAJAIBAN TOKO KELONTONG NAMIYA | C24: 800 | KESUSASTRAAN | D24: 813 | E24: NOVEL | F24: KEIGO HIGASHINO / FAIRA AMALIA | G24: Pandam Kuntaswari | H24: PT Gramedia Pustaka Utama, Jakarta | I24: 978-602-06-4828-6 | J24: 2020 | K24: 400 hlm.; 20 cm | L24: 1 | M24: e 813 Keajaiban toko kelontong namiya.jpg | N24: =D24 & CHAR(10) & LEFT(F24,3) & CHAR(10) & LOWER(LEFT(B24,1)) -> 813 KEI k
A25: 24 | B25: KELUARGA TAK KASAT MATA | C25: 800 | KESUSASTRAAN | D25: 813 | E25: NOVEL | F25: BONAVENTURA GENTA | H25: GagasMedia, Jakarta | I25: 978-979-780-803-7 | J25: 2016 | K25: vi + 122 hlm.; 13 x 19 cm | L25: 1 | M25: e 813 Keluarga Tak Kasatmata.jpg | N25: =D25 & CHAR(10) & LEFT(F25,3) & CHAR(10) & LOWER(LEFT(B25,1)) -> 813 BON k
A26: 25 | B26: GUNDALA: PUTRA PETIR - ASAL-USUL | C26: 800 | KESUSASTRAAN | D26: 813 | E26: NOVEL GRAFIS | F26: HARYA SURAMINATA | G26: Rizqi R. Mosmarth & Aji Raditya | H26: m&c! / PT Gramedia Pustaka Utama, Jakarta | K26: 64 hlm.; 17 x 24,5 cm | L26: 1 | M26: e 813 Gundala Putera Petir.jpg | N26: =D26 & CHAR(10) & LEFT(F26,3) & CHAR(10) & LOWER(LEFT(B26,1)) -> 813 HAR g
A27: 26 | B27: AGATHA CHRISTIE'S THE BEST OF MISS MARPLE | C27: 800 | KESUSASTRAAN | D27: 813 | E27: NOVEL | F27: AGATHA CHRISTIE / BUDIJANTO T. PRAMONO | H27: PT Gramedia Pustaka Utama, Jakarta | I27: 978-602-065-053-1 | J27: 2021 | K27: 648 hlm.; 23 cm | L27: 1 | M27: e 813 The Best of Miss Marple.jpg | N27: =D27 & CHAR(10) & LEFT(F27,3) & CHAR(10) & LOWER(LEFT(B27,1)) -> 813 AGA a
A28: 27 | B28: MARPLE: TWELVE NEW STORIES | C28: 800 | KESUSASTRAAN | D28: 813 | E28: NOVEL | N28: =D28 & CHAR(10) & LEFT(F28,3) & CHAR(10) & LOWER(LEFT(B28,1)) -> 813 m
N29: =D29 & CHAR(10) & LEFT(F29,3) & CHAR(10) & LOWER(LEFT(B29,1))
N30: =D30 & CHAR(10) & LEFT(F30,3) & CHAR(10) & LOWER(LEFT(B30,1))
N31: =D31 & CHAR(10) & LEFT(F31,3) & CHAR(10) & LOWER(LEFT(B31,1))
N32: =D32 & CHAR(10) & LEFT(F32,3) & CHAR(10) & LOWER(LEFT(B32,1))
N33: =D33 & CHAR(10) & LEFT(F33,3) & CHAR(10) & LOWER(LEFT(B33,1))
N34: =D34 & CHAR(10) & LEFT(F34,3) & CHAR(10) & LOWER(LEFT(B34,1))
N35: =D35 & CHAR(10) & LEFT(F35,3) & CHAR(10) & LOWER(LEFT(B35,1))
N36: =D36 & CHAR(10) & LEFT(F36,3) & CHAR(10) & LOWER(LEFT(B36,1))
N37: =D37 & CHAR(10) & LEFT(F37,3) & CHAR(10) & LOWER(LEFT(B37,1))
N38: =D38 & CHAR(10) & LEFT(F38,3) & CHAR(10) & LOWER(LEFT(B38,1))
N39: =D39 & CHAR(10) & LEFT(F39,3) & CHAR(10) & LOWER(LEFT(B39,1))
N40: =D40 & CHAR(10) & LEFT(F40,3) & CHAR(10) & LOWER(LEFT(B40,1))
...

Sheet BUKU PAKET
A1: NO | B1: TANGGAL | C1: JUDUL BUKU | D1: KELAS | E1: KATEGORI | F1: KURIKULUM | G1: PENULIS | H1: EDITOR | I1: PENERBIT | J1: ISBN | K1: TAHUN | L1: JML HAL | M1: JML BUKU | N1: NOMOR INDUK | O1: GAMBAR
A2: 1 | B2: 44781 | C2: PENDIDIKAN PANCASILA DAN KEWARGANEGARAAN | KELAS VII | KEMDIKBUDRISTEK | KUMER | D2: VII | E2: BUKU PEGANGAN SISWA | F2: MERDEKA BELAJAR | G2: ZAIM UCHROWI RUSLINAWATI | H2: SUNAN HASAN | I2: KEMENDIKBUDRISTEK | J2: 978-602-244-312-4 | K2: 2021 | L2: 142 hlm.: 17,6 × 25 cm | M2: 256 | N2: 1 s/d 256 | O2: PPKN KELAS VII.jpg
A3: 2 | B3: 44781 | C3: BAHASA INDONESIA | KELAS VII | KEMDIKBUDRISTEK | KUMER | D3: VII | E3: BUKU PEGANGAN SISWA | F3: MERDEKA BELAJAR | G3: RAKHMA SUBARNA SOFIE DEWAYANI C. ERNI SETYOWATI | H3: TRI HARTINI | I3: KEMENDIKBUDRISTEK | J3: 978-602-244-298-1 | K3: 2021 | L3: 220 hlm. 17.6 x 25 cm | M3: 256 | N3: 1 s/d 256 | O3: BAHASA INDONESIA KELAS VII.png
A4: 3 | B4: 44781 | C4: MATEMATIKA | KELAS VII | KEMDIKBUDRISTEK | KUMER | D4: VII | E4: BUKU PEGANGAN SISWA | F4: MERDEKA BELAJAR | G4: TIM GAKKO TOSHO | H4: ZULKARDI, LAMBAS, YUDI SATRIA, FRISTALINA | I4: KEMENDIKBUDRISTEK | J4: 978-602-244-514-2 | K4: 2021 | L4: 314 hlm.: 18,2 x 25,7 cm | M4: 256 | N4: 1 s/d 256 | O4: MATEMATIKA KELAS VII.png
A5: 4 | B5: 44781 | C5: ILMU PENGETAHUAN ALAM | KELAS VII | KEMDIKBUDRISTEK | KUMER | D5: VII | E5: BUKU PEGANGAN SISWA | F5: MERDEKA BELAJAR | G5: VICTORIANI INABUY CECE SUTIA OKKY FAJAR TRI MARYANA BUDIYANTI DWI HARDANIE SRI HANDAYANI LESTARI | H5: ANDRI NURDIANSYAH LALA TANSAH | I5: KEMENDIKBUDRISTEK | J5: 978-602-244-383-4 | K5: 2021 | L5: 264 hlm.: 17,6 x 25 cm | M5: 256 | N5: 1 s/d 256 | O5: IPA KELAS VII.png
A6: 5 | B6: 44781 | C6: INFORMATIKA | KELAS VII | KEMDIKBUDRISTEK | KUMER | D6: VII | E6: BUKU PEGANGAN SISWA | F6: MERDEKA BELAJAR | G6: MARESHA CAROLINE WIJANTO, DKK. | H6: CECILIA ESTI NUGRAHENI, CHRISTINA TULALESSY | I6: KEMENDIKBUDRISTEK | J6: 978-602-244-427-5 | K6: 2021 | L6: 286 hlm.: 17,6 x 25 cm | M6: 194 | N6: 1 s/d 194 | O6: INFORMATIKA KELAS VII.jpg
A7: 6 | B7: 44789 | C7: ILMU PENGETAHUAN SOSIAL | KELAS VII | KEMDIKBUDRISTEK | KUMER | D7: VII | E7: BUKU PEGANGAN SISWA | F7: MERDEKA BELAJAR | G7: M. NURSA’BAN, SUPARDI, MOHAMMAD RIZKY SATRIA, SARI OKTAFIANA | H7: EKA WARDANA, HARTATI | I7: KEMENDIKBUDRISTEK | J7: 978-602-244-307-0 | K7: 2021 | L7: 286 hlm: 17,6 cm x 25 cm | M7: 256 | N7: 1 s/d 256 | O7: IPS KELAS VII.jpg
A8: 7 | B8: 44789 | C8: ENGLISH FOR NUSANTARA | KELAS VII | KEMDIKBUDRISTEK | KUMER | D8: VII | E8: BUKU PEGANGAN SISWA | F8: MERDEKA BELAJAR | G8: IKA LESTARI DAMAYANTI, DKK. | H8: KRISTINE ANN M. CAPA, MADE AYU UTAMI CHANDRA DEWINA | I8: KEMENDIKBUDRISTEK | J8: 978-602-244-884-6 | K8: 2022 | L8: 264 hlm.: 17,6 x 25 cm | M8: 256 | N8: 1 s/d 256 | O8: BAHASA INGGRIS KELAS VII.png
A9: 8 | B9: 44795 | C9: PENDIDIKAN AGAMA ISLAM DAN BUDI PEKERTI | KELAS VII | KEMDIKBUDRISTEK | KUMER | D9: VII | E9: BUKU PEGANGAN SISWA | F9: MERDEKA BELAJAR | G9: RUDI AHMAD SURYADI SUMIYATI | H9: ASEP ANDI RAHMAN | I9: KEMENDIKBUDRISTEK | J9: 978-602-244-433-6 | K9: 2021 | L9: 272 hlm.: 17,6 x 25 cm | M9: 256 | N9: 1 s/d 256 | O9: PAI KELAS VII.jpg
A10: 9 | B10: 44795 | C10: INFORMATIKA | KELAS VII | KEMDIKBUDRISTEK | KUMER | D10: VII | E10: BUKU PEGANGAN SISWA | F10: MERDEKA BELAJAR | G10: MARESHA CAROLINE WIJANTO, DKK. | H10: CECILIA ESTI NUGRAHENI, CHRISTINA TULALESSY | I10: KEMENDIKBUDRISTEK | J10: 978-602-244-427-5 | K10: 2021 | L10: 286 hlm.: 17,6 x 25 cm | M10: 62 | N10: 195 s/d 256 | O10: INFORMATIKA KELAS VII.jpg
A11: 10 | B11: 45069 | C11: MATEMATIKA | KELAS VIII | KEMDIKBUDRISTEK | KUMER | D11: VIII | E11: BUKU PEGANGAN SISWA | F11: MERDEKA BELAJAR | G11: TIM GAKKO TOSHO | H11: ULY AMALIA | I11: KEMENDIKBUDRISTEK | J11: 978-602-244-514-2 | K11: 2021 | L11: 262 hlm.: 21 × 29,7 cm | M11: 252 | N11: 1 s/d 252 | O11: MATEMATIKA KELAS VIII.png
A12: 11 | B12: 45069 | C12: ILMU PENGETAHUAN SOSIAL | KELAS VIII | KEMDIKBUDRISTEK | KUMER | D12: VIII | E12: BUKU PEGANGAN SISWA | F12: MERDEKA BELAJAR | G12: SUPARDI, DKK. | H12: EKA WARDANA, HARTATI | I12: KEMENDIKBUDRISTEK | J12: 978-602-244-468-8 | K12: 2021 | L12: 320 hlm: 17,6 cm x 25 cm | M12: 252 | N12: 1 s/d 252 | O12: IPS KELAS VIII.jpg
A13: 12 | B13: 45069 | C13: PENDIDIKAN AGAMA ISLAM DAN BUDI PEKERTI | KELAS VIII | KEMDIKBUDRISTEK | KUMER | D13: VIII | E13: BUKU PEGANGAN SISWA | F13: MERDEKA BELAJAR | G13: TATIK PUDJIANI, BAGUS MUSTAKIM | H13: KOKO KHOERUDIN | I13: KEMENDIKBUDRISTEK | J13: 978-602-244-433-6 | K13: 2021 | L13: 292 hlm. : 17,6 x 25 cm. | M13: 252 | N13: 1 s/d 252 | O13: PAI KELAS VIII.jpg
A14: 13 | B14: 45069 | C14: ENGLISH FOR NUSANTARA | KELAS VIII | KEMDIKBUDRISTEK | KUMER | D14: VIII | E14: BUKU PEGANGAN SISWA | F14: MERDEKA BELAJAR | G14: IKA LESTARI DAMAYANTI IYEN NURLAELAWATI MAHMUD LAYAN HUTASUHUT YUSNITA FEBRIANTI RAYMON RAHMADHANI GILANG ASRI DEVIANTY | H14: KRISTINE ANN MANREAL CAPA | I14: KEMENDIKBUDRISTEK | J14: 978-602-244-884-6 | K14: 2022 | L14: 312 hlm.: 17,6 x 25 cm | M14: 252 | N14: 1 s/d 252 | O14: BAHASA INGGRIS KELAS VIII.jpg
A15: 14 | B15: 45069 | C15: PJOK | KELAS VIII | MEDIA MANDIRI | KUMER | D15: VIII | E15: BUKU PEGANGAN SISWA | F15: MERDEKA BELAJAR | G15: TIM MEDIA MANDIRI | H15: TIM MEDIA MANDIRI | I15: MEDIA MANDIRI | K15: 2022 | L15: 192 hlm : 17,6 x 25 cm | M15: 252 | N15: 1 s/d 252 | O15: PJOK KELAS VIII.jpeg
A16: 15 | B16: 45069 | C16: SENI RUPA | KELAS VIII | MEDIA MANDIRI | KUMER | D16: VIII | E16: BUKU PEGANGAN SISWA | F16: MERDEKA BELAJAR | G16: TIM MEDIA MANDIRI | H16: TIM MEDIA MANDIRI | I16: MEDIA MANDIRI | J16: 978-623-09-0926-9 | K16: 2022 | L16: 118 hlm : 17,6 x 25 cm | M16: 138 | N16: 1 s/d 138 | O16: SENI RUPA KELAS VIII.webp
A17: 16 | B17: 45069 | C17: PANDUAN GURU - PENDIDIKAN KEWARGANEGARAAN | KELAS VIII | KEMDIKBUDRISTEK | KUMER | D17: VIII | E17: BUKU PEGANGAN GURU | F17: MERDEKA BELAJAR | I17: KEMENDIKBUDRISTEK | M17: 2 | N17: 1 s/d 2 | O17: PPKN PG KELAS VIII.jpg
A18: 17 | B18: 45069 | C18: PANDUAN GURU - BAHASA INDONESIA | KELAS VIII | KEMDIKBUDRISTEK | KUMER | D18: VIII | E18: BUKU PEGANGAN GURU | F18: MERDEKA BELAJAR | G18: MAYA LESTARI GUSFITRI, ELLY DELFIA | H18: CICILIA HENI LESTARI | I18: KEMENDIKBUDRISTEK | J18: 978-602-244-398-8 | K18: 2021 | L18: 214 hlm. 17.6 x 25 cm | M18: 2 | N18: 1 s/d 2 | O18: BAHASA INDONESIA PG KELAS VIII.png
A19: 18 | B19: 45069 | C19: PANDUAN GURU - MATEMATIKA | KELAS VIII | KEMDIKBUDRISTEK | KUMER | D19: VIII | E19: BUKU PEGANGAN GURU | F19: MERDEKA BELAJAR | G19: TIM GAKKO TOSHO | H19: ULY AMALIA | I19: KEMENDIKBUDRISTEK | J19: 978-602-244-516-6 | K19: 2021 | L19: 262 hlm.: 21 × 29,7 cm | M19: 2 | N19: 1 s/d 2 | O19: MATEMATIKA PG KELAS VIII.png
A20: 19 | B20: 45069 | C20: PANDUAN GURU - ILMU PENGETAHUAN ALAM | KELAS VIII | KEMDIKBUDRISTEK | KUMER | D20: VIII | E20: BUKU PEGANGAN GURU | F20: MERDEKA BELAJAR | G20: SRI HANDAYANI LESTARI, DKK. | H20: LALA TANSAH ANDRI NURDIANSYAH | I20: KEMENDIKBUDRISTEK | J20: 978-602-244-381-0 | K20: 2021 | L20: 198 hlm.: 17,6 × 25 cm | M20: 2 | N20: 1 s/d 2 | O20: IPA PG KELAS VIII.png
A21: 20 | B21: 45069 | C21: PANDUAN GURU - ILMU PENGETAHUAN SOSIAL | KELAS VIII | KEMDIKBUDRISTEK | KUMER | D21: VIII | E21: BUKU PEGANGAN GURU | F21: MERDEKA BELAJAR | G21: SUPARDI, DKK. | H21: EKA WARDANA, HARTATI | I21: KEMENDIKBUDRISTEK | J21: 978-602-244-326-1 | K21: 2021 | L21: 376 hlm: 17,6 cm x 25 cm | M21: 2 | N21: 1 S/d 2 | O21: IPS PG KELAS VIII.png
A22: 21 | B22: 45069 | C22: PANDUAN GURU - SENI RUPA | KELAS VIII | KEMDIKBUDRISTEK | KUMER | D22: VIII | E22: BUKU PEGANGAN GURU | F22: MERDEKA BELAJAR | G22: RASJOYO, AHMAD MUTOHAR | H22: MESRA | I22: KEMENDIKBUDRISTEK | J22: 978-602-244-621-7 | K22: 2021 | L22: 226 hlm.: 17,6 X 25 cm | M22: 2 | N22: 1 s/d 2 | O22: SENI RUPA PG KELAS VIII.png
A23: 22 | B23: 45069 | C23: PANDUAN GURU - SENI MUSIK | KELAS VIII | KEMDIKBUDRISTEK | KUMER | D23: VIII | E23: BUKU PEGANGAN GURU | F23: MERDEKA BELAJAR | G23: CAECILIA HARDIARINI, DKK | H23: SENI ASIATI | I23: KEMENDIKBUDRISTEK | J23: 978-602-244-603-3 | K23: 2021 | L23: 218 hlm., 17.6 x 25 cm | M23: 2 | N23: 1 s/d 2 | O23: SENI MUSIK PG KELAS VIII.png
A24: 23 | B24: 45069 | C24: PANDUAN GURU - SENI TARI | KELAS VIII | KEMDIKBUDRISTEK | KUMER | D24: VIII | E24: BUKU PEGANGAN GURU | F24: MERDEKA BELAJAR | G24: FITRI DARYANTI, WIDA RAHAYUNINGTYAS | H24: EKA SOFIA AGUSTINA | I24: KEMENDIKBUDRISTEK | J24: 978-602-244-723-8 | K24: 2021 | L24: 252 hlm: 17,6 × 25 cm | M24: 2 | N24: 1 s/d 2 | O24: SENI TARI PG KELAS VIII.png
A25: 24 | B25: 45069 | C25: PANDUAN GURU - PENDIDIKAN JASMANI, OLAHRAGA, DAN KESEHATAN | KELAS VIII | KEMDIKBUDRISTEK | KUMER | D25: VIII | E25: BUKU PEGANGAN GURU | F25: MERDEKA BELAJAR | G25: MUHAJIR, AGUS GUNAWAN | H25: IDA NURHAIDA | I25: KEMENDIKBUDRISTEK | J25: 978-602-244-302-5 | K25: 2021 | L25: 266 hlm.: 17,6 × 25 cm | M25: 2 | N25: 1 s/d 2 | O25: PJOK PG KELAS VIII.png
A26: 25 | B26: 45069 | C26: PANDUAN GURU - PENDIDIKAN AGAMA DAN BUDI PEKERTI | KELAS VIII | KEMDIKBUDRISTEK | KUMER | D26: VIII | E26: BUKU PEGANGAN GURU | F26: MERDEKA BELAJAR | G26: TATIK PUDJIANI, BAGUS MUSTAKIM | H26: KOKO KHOERUDIN | I26: KEMENDIKBUDRISTEK | J26: 978-602-244-437-4 | K26: 2021 | L26: 188 hlm.: 17,6 x 25 cm | M26: 2 | N26: 1 s/d 2 | O26: PAI PG KELAS VIII.png
A27: 26 | B27: 45069 | C27: PANDUAN GURU - ENGLISH FOR NUSANTARA | KELAS VIII | KEMDIKBUDRISTEK | KUMER | D27: VIII | E27: BUKU PEGANGAN GURU | F27: MERDEKA BELAJAR | G27: IKA LESTARI DAMAYANTI, DKK. | H27: MADE AYU UTAMI CHANDRA DEWINA | I27: KEMENDIKBUDRISTEK | J27: 978-602-244-886-0 | K27: 2022 | L27: 422 hlm.: 17,6 x 25 cm. | M27: 2 | N27: 1 s/d 2 | O27: BAHASA INGGRIS PG KELAS VIII.png
A28: 27 | B28: 45070 | C28: GAPURA BASA | KELAS VII | GEGER SUNTEN | KUMER | D28: VII | E28: BUKU PENDAMPING | F28: MERDEKA BELAJAR | G28: Drs. TATANG SUMARSONO Drs. TAUFIK FATUROHMAN | I28: CV GEGER SUNTEN | J28: 978-623-7728-50-4 | K28: 2022 | L28: 152 hlm: 17,6 x 25 cm | M28: 96 | O28: GAPURA BASA KELAS VII.jpg
A29: 28 | B29: 45070 | C29: GAPURA BASA | KELAS VIII | GEGER SUNTEN | KUMER | D29: VIII | E29: BUKU PENDAMPING | F29: MERDEKA BELAJAR | G29: Drs. TATANG SUMARSONO Drs. TAUFIK FATUROHMAN | I29: CV GEGER SUNTEN | J29: 978-623-7728-49-8 | K29: 2022 | L29: 152 hlm: 17,6 x 25 cm | M29: 96 | O29: GAPURA BASA KELAS VIII.jpg
A30: 29 | B30: 45077 | C30: BAHASA INDONESIA | KELAS VIII | KEMDIKBUDRISTEK | KUMER | D30: VIII | E30: BUKU PEGANGAN SISWA | F30: MERDEKA BELAJAR | G30: MAYA LESTARI GUSFITRI, ELLY DELFIA | H30: CICILIA HENI LESTARI | I30: KEMENDIKBUDRISTEK | J30: 978-602-244-622-4 | K30: 2021 | L30: 204 hlm 17,6 x 25 cm | M30: 252 | N30: 1 s/d 252 | O30: BAHASA INDONESIA KELAS VIII.png
A31: 30 | B31: 45077 | C31: ILMU PENGETAHUAN ALAM | KELAS VIII | KEMDIKBUDRISTEK | KUMER | D31: VIII | E31: BUKU PEGANGAN SISWA | F31: MERDEKA BELAJAR | G31: OKKY FAJAR TRI MARYANA, VICTORIANI INABUY, CECE SUTIA, BUDIYANTI DWI HARDANIE, SRI HANDAYANI LESTARI | H31: LALA TANSAH, ANDRI NURDIANSYAH | I31: KEMENDIKBUDRISTEK | J31: 978-602-244-794-8 | K31: 2021 | L31: 234 hlm,17,6 x 25 cm | M31: 252 | N31: 1 s/d 252 | O31: IPA KELAS VIII.webp
A32: 31 | B32: 45077 | C32: PENDIDIKAN PANCASILA DAN KEWARGANEGARAAN | KELAS VIII | KEMDIKBUDRISTEK | KUMER | D32: VIII | E32: BUKU PEGANGAN SISWA | F32: MERDEKA BELAJAR | G32: MUHAMMAD SAPEI, TREZADIGJAYA, PRAYOGO | H32: YOCTA NUR RAHMAN | I32: KEMENDIKBUDRISTEK | J32: 978-602-244-312-4 | K32: 2022 | L32: 156 hlm, 17,6 x 25 cm | M32: 252 | N32: 1 s/d 252 | O32: PKN KELAS VIII.jpg
A33: 32 | B33: 45132 | C33: MATEMATIKA | KELAS VII | KEMDIKBUDRISTEK | KUMER | D33: VII | E33: BUKU PEGANGAN SISWA | F33: MERDEKA BELAJAR | G33: TIM GAKKO TOSHO | H33: ZULKARDI, LAMBAS, YUDI SATRIA, FRISTALINA | I33: KEMENDIKBUDRISTEK | J33: 978-602-244-514-2 | K33: 2021 | L33: 314 hlm.: 18,2 x 25,7 cm | M33: 30 | N33: 257 s/d 286 | O33: MATEMATIKA KELAS VII.png
A34: 33 | B34: 45132 | C34: BAHASA INDONESIA | KELAS VII | KEMDIKBUDRISTEK | KUMER | D34: VII | E34: BUKU PEGANGAN SISWA | F34: MERDEKA BELAJAR | G34: RAKHMA SUBARNA SOFIE DEWAYANI C. ERNI SETYOWATI | H34: TRI HARTINI | I34: KEMENDIKBUDRISTEK | J34: 978-602-244-298-1 | K34: 2021 | L34: 220 hlm. 17.6 x 25 cm | M34: 30 | N34: 257 s/d 286 | O34: BAHASA INDONESIA KELAS VII.png
A35: 34 | B35: 45132 | C35: ENGLISH FOR NUSANTARA | KELAS VII | KEMDIKBUDRISTEK | KUMER | D35: VII | E35: BUKU PEGANGAN SISWA | F35: MERDEKA BELAJAR | G35: IKA LESTARI DAMAYANTI, DKK. | H35: KRISTINE ANN M. CAPA, MADE AYU UTAMI CHANDRA DEWINA | I35: KEMENDIKBUDRISTEK | J35: 978-602-244-884-6 | K35: 2022 | L35: 264 hlm.: 17,6 x 25 cm | M35: 30 | N35: 257 s/d 286 | O35: BAHASA INGGRIS KELAS VII.png
A36: 35 | B36: 45132 | C36: ILMU PENGETAHUAN ALAM | KELAS VII | KEMDIKBUDRISTEK | KUMER | D36: VII | E36: BUKU PEGANGAN SISWA | F36: MERDEKA BELAJAR | G36: VICTORIANI INABUY CECE SUTIA OKKY FAJAR TRI MARYANA BUDIYANTI DWI HARDANIE SRI HANDAYANI LESTARI | H36: ANDRI NURDIANSYAH LALA TANSAH | I36: KEMENDIKBUDRISTEK | J36: 978-602-244-383-4 | K36: 2021 | L36: 264 hlm.: 17,6 x 25 cm | M36: 30 | N36: 257 s/d 286 | O36: IPA KELAS VII.png
A37: 36 | B37: 45132 | C37: PENDIDIKAN PANCASILA DAN KEWARGANEGARAAN | KELAS VII | KEMDIKBUDRISTEK | KUMER | D37: VII | E37: BUKU PEGANGAN SISWA | F37: MERDEKA BELAJAR | G37: ZAIM UCHROWI RUSLINAWATI | H37: SUNAN HASAN | I37: KEMENDIKBUDRISTEK | J37: 978-602-244-312-4 | K37: 2021 | L37: 142 hlm.: 17,6 × 25 cm | M37: 30 | N37: 257 s/d 286 | O37: PPKN KELAS VII.jpg
A38: 37 | B38: 45132 | C38: ILMU PENGETAHUAN SOSIAL | KELAS VII | KEMDIKBUDRISTEK | KUMER | D38: VII | E38: BUKU PEGANGAN SISWA | F38: MERDEKA BELAJAR | G38: M. NURSA’BAN, SUPARDI, MOHAMMAD RIZKY SATRIA, SARI OKTAFIANA | H38: EKA WARDANA, HARTATI | I38: KEMENDIKBUDRISTEK | J38: 978-602-244-307-0 | K38: 2021 | L38: 286 hlm: 17,6 cm x 25 cm | M38: 30 | N38: 257 s/d 286 | O38: IPS KELAS VII.jpg
A39: 38 | B39: 45132 | C39: PENDIDIKAN AGAMA ISLAM DAN BUDI PEKERTI | KELAS VII | KEMDIKBUDRISTEK | KUMER | D39: VII | E39: BUKU PEGANGAN SISWA | F39: MERDEKA BELAJAR | G39: RUDI AHMAD SURYADI SUMIYATI | H39: ASEP ANDI RAHMAN | I39: KEMENDIKBUDRISTEK | J39: 978-602-244-433-6 | K39: 2021 | L39: 272 hlm.: 17,6 x 25 cm | M39: 30 | N39: 257 s/d 286 | O39: PAI KELAS VII.jpg
A40: 39 | B40: 45135 | C40: INFORMATIKA | KELAS VII | KEMDIKBUDRISTEK | KUMER | D40: VII | E40: BUKU PEGANGAN SISWA | F40: MERDEKA BELAJAR | G40: MARESHA CAROLINE WIJANTO, DKK. | H40: CECILIA ESTI NUGRAHENI, CHRISTINA TULALESSY | I40: KEMENDIKBUDRISTEK | J40: 978-602-244-427-5 | K40: 2021 | L40: 286 hlm.: 17,6 x 25 cm | M40: 2 | N40: 257 s/d 258 | O40: INFORMATIKA KELAS VII.jpg
...

Sheet LAPORAN BUKU
A1: JUMLAH JUDUL BUKU
A2: KATEGORI BUKU | B2: JUMLAH
A3: 000 | KARYA UMUM | B3: =COUNTIF('BUKU FIKSI&NON FIKSI'!$C$2:$C$1749,$A3) -> 28
A4: 100 | FILSAFAT & PSIKOLOGI | B4: =COUNTIF('BUKU FIKSI&NON FIKSI'!$C$2:$C$1749,$A4) -> 63
A5: 200 | AGAMA | B5: =COUNTIF('BUKU FIKSI&NON FIKSI'!$C$2:$C$1749,$A5) -> 101
A6: 300 | ILMU SOSIAL | B6: =COUNTIF('BUKU FIKSI&NON FIKSI'!$C$2:$C$1749,$A6) -> 323
A7: 400 | BAHASA | B7: =COUNTIF('BUKU FIKSI&NON FIKSI'!$C$2:$C$1749,$A7) -> 64
A8: 500 | ILMU MURNI | B8: =COUNTIF('BUKU FIKSI&NON FIKSI'!$C$2:$C$1749,$A8) -> 271
A9: 600 | ILMU TERAPAN | B9: =COUNTIF('BUKU FIKSI&NON FIKSI'!$C$2:$C$1749,$A9) -> 232
A10: 700 | SENI DAN OLAHRAGA | B10: =COUNTIF('BUKU FIKSI&NON FIKSI'!$C$2:$C$1749,$A10) -> 108
A11: 800 | KESUSASTRAAN | B11: =COUNTIF('BUKU FIKSI&NON FIKSI'!$C$2:$C$1749,$A11) -> 406
A12: 900 | SEJARAH & GEOGRAFI | B12: =COUNTIF('BUKU FIKSI&NON FIKSI'!$C$2:$C$1749,$A12) -> 142
A13: TOTAL | B13: =SUM(B3:B12) -> 1738
